{
  "test_run_summary": {
    "timestamp": "2025-06-22T12:44:05.443230",
    "total_execution_time": 1.9293980598449707,
    "total_test_runs": 1,
    "successful_runs": 0,
    "failed_runs": 1,
    "success_rate": 0.0
  },
  "test_results": [
    {
      "status": "completed",
      "description": "Quick Tests",
      "return_code": 3,
      "execution_time": 1.812398910522461,
      "stdout": "============================= test session starts ==============================\nplatform darwin -- Python 3.11.4, pytest-8.4.0, pluggy-1.6.0 -- /Users/macbookpro/M4_Projects/AIEngineer/backend_ai_popup/venv/bin/python\ncachedir: .pytest_cache\nmetadata: {'Python': '3.11.4', 'Platform': 'macOS-15.3.1-x86_64-i386-64bit', 'Packages': {'pytest': '8.4.0', 'pluggy': '1.6.0'}, 'Plugins': {'xdist': '3.7.0', 'anyio': '4.9.0', 'sugar': '1.0.0', 'html': '4.1.1', 'Faker': '37.4.0', 'timeout': '2.4.0', 'metadata': '3.1.1', 'clarity': '1.0.1', 'doctestplus': '1.4.0', 'cov': '6.2.1', 'mock': '3.14.1', 'langsmith': '0.3.45', 'redis': '3.1.3', 'benchmark': '5.1.0', 'asyncio': '1.0.0', 'postgresql': '7.0.2'}, 'JAVA_HOME': '/Library/Java/JavaVirtualMachines/jdk-17.jdk/Contents/Home'}\nbenchmark: 5.1.0 (defaults: timer=time.perf_counter disable_gc=False min_rounds=5 min_time=0.000005 max_time=1.0 calibration_precision=10 warmup=False warmup_iterations=100000)\nrootdir: /Users/macbookpro/M4_Projects/AIEngineer/backend_ai_popup\nconfigfile: pytest.ini\nplugins: xdist-3.7.0, anyio-4.9.0, sugar-1.0.0, html-4.1.1, Faker-37.4.0, timeout-2.4.0, metadata-3.1.1, clarity-1.0.1, doctestplus-1.4.0, cov-6.2.1, mock-3.14.1, langsmith-0.3.45, redis-3.1.3, benchmark-5.1.0, asyncio-1.0.0, postgresql-7.0.2\nasyncio: mode=Mode.STRICT, asyncio_default_fixture_loop_scope=None, asyncio_default_test_loop_scope=function\ncollecting ... Error: Could not import resume_extractor module.\nMake sure resume_extractor.py is in the current directory.\ncollected 21 items / 1 error\nINTERNALERROR> Traceback (most recent call last):\nINTERNALERROR>   File \"/Users/macbookpro/M4_Projects/AIEngineer/backend_ai_popup/tests/unit/test_resume_extractor.py\", line 24, in <module>\nINTERNALERROR>     from resume_extractor import (\nINTERNALERROR> ModuleNotFoundError: No module named 'resume_extractor'\nINTERNALERROR> \nINTERNALERROR> During handling of the above exception, another exception occurred:\nINTERNALERROR> \nINTERNALERROR> Traceback (most recent call last):\nINTERNALERROR>   File \"/Users/macbookpro/M4_Projects/AIEngineer/backend_ai_popup/venv/lib/python3.11/site-packages/_pytest/main.py\", line 289, in wrap_session\nINTERNALERROR>     session.exitstatus = doit(config, session) or 0\nINTERNALERROR>                          ^^^^^^^^^^^^^^^^^^^^^\nINTERNALERROR>   File \"/Users/macbookpro/M4_Projects/AIEngineer/backend_ai_popup/venv/lib/python3.11/site-packages/_pytest/main.py\", line 342, in _main\nINTERNALERROR>     config.hook.pytest_collection(session=session)\nINTERNALERROR>   File \"/Users/macbookpro/M4_Projects/AIEngineer/backend_ai_popup/venv/lib/python3.11/site-packages/pluggy/_hooks.py\", line 512, in __call__\nINTERNALERROR>     return self._hookexec(self.name, self._hookimpls.copy(), kwargs, firstresult)\nINTERNALERROR>            ^^^^^^^^^^^^^^^^^^^^^^^^^^^^^^^^^^^^^^^^^^^^^^^^^^^^^^^^^^^^^^^^^^^^^^\nINTERNALERROR>   File \"/Users/macbookpro/M4_Projects/AIEngineer/backend_ai_popup/venv/lib/python3.11/site-packages/pluggy/_manager.py\", line 120, in _hookexec\nINTERNALERROR>     return self._inner_hookexec(hook_name, methods, kwargs, firstresult)\nINTERNALERROR>            ^^^^^^^^^^^^^^^^^^^^^^^^^^^^^^^^^^^^^^^^^^^^^^^^^^^^^^^^^^^^^\nINTERNALERROR>   File \"/Users/macbookpro/M4_Projects/AIEngineer/backend_ai_popup/venv/lib/python3.11/site-packages/pluggy/_callers.py\", line 167, in _multicall\nINTERNALERROR>     raise exception\nINTERNALERROR>   File \"/Users/macbookpro/M4_Projects/AIEngineer/backend_ai_popup/venv/lib/python3.11/site-packages/pluggy/_callers.py\", line 139, in _multicall\nINTERNALERROR>     teardown.throw(exception)\nINTERNALERROR>   File \"/Users/macbookpro/M4_Projects/AIEngineer/backend_ai_popup/venv/lib/python3.11/site-packages/_pytest/logging.py\", line 788, in pytest_collection\nINTERNALERROR>     return (yield)\nINTERNALERROR>             ^^^^^\nINTERNALERROR>   File \"/Users/macbookpro/M4_Projects/AIEngineer/backend_ai_popup/venv/lib/python3.11/site-packages/pluggy/_callers.py\", line 139, in _multicall\nINTERNALERROR>     teardown.throw(exception)\nINTERNALERROR>   File \"/Users/macbookpro/M4_Projects/AIEngineer/backend_ai_popup/venv/lib/python3.11/site-packages/_pytest/warnings.py\", line 99, in pytest_collection\nINTERNALERROR>     return (yield)\nINTERNALERROR>             ^^^^^\nINTERNALERROR>   File \"/Users/macbookpro/M4_Projects/AIEngineer/backend_ai_popup/venv/lib/python3.11/site-packages/pluggy/_callers.py\", line 139, in _multicall\nINTERNALERROR>     teardown.throw(exception)\nINTERNALERROR>   File \"/Users/macbookpro/M4_Projects/AIEngineer/backend_ai_popup/venv/lib/python3.11/site-packages/_pytest/config/__init__.py\", line 1450, in pytest_collection\nINTERNALERROR>     return (yield)\nINTERNALERROR>             ^^^^^\nINTERNALERROR>   File \"/Users/macbookpro/M4_Projects/AIEngineer/backend_ai_popup/venv/lib/python3.11/site-packages/pluggy/_callers.py\", line 121, in _multicall\nINTERNALERROR>     res = hook_impl.function(*args)\nINTERNALERROR>           ^^^^^^^^^^^^^^^^^^^^^^^^^\nINTERNALERROR>   File \"/Users/macbookpro/M4_Projects/AIEngineer/backend_ai_popup/venv/lib/python3.11/site-packages/_pytest/main.py\", line 353, in pytest_collection\nINTERNALERROR>     session.perform_collect()\nINTERNALERROR>   File \"/Users/macbookpro/M4_Projects/AIEngineer/backend_ai_popup/venv/lib/python3.11/site-packages/_pytest/main.py\", line 813, in perform_collect\nINTERNALERROR>     self.items.extend(self.genitems(node))\nINTERNALERROR>   File \"/Users/macbookpro/M4_Projects/AIEngineer/backend_ai_popup/venv/lib/python3.11/site-packages/_pytest/main.py\", line 979, in genitems\nINTERNALERROR>     yield from self.genitems(subnode)\nINTERNALERROR>   File \"/Users/macbookpro/M4_Projects/AIEngineer/backend_ai_popup/venv/lib/python3.11/site-packages/_pytest/main.py\", line 979, in genitems\nINTERNALERROR>     yield from self.genitems(subnode)\nINTERNALERROR>   File \"/Users/macbookpro/M4_Projects/AIEngineer/backend_ai_popup/venv/lib/python3.11/site-packages/_pytest/main.py\", line 974, in genitems\nINTERNALERROR>     rep, duplicate = self._collect_one_node(node, handle_dupes)\nINTERNALERROR>                      ^^^^^^^^^^^^^^^^^^^^^^^^^^^^^^^^^^^^^^^^^^\nINTERNALERROR>   File \"/Users/macbookpro/M4_Projects/AIEngineer/backend_ai_popup/venv/lib/python3.11/site-packages/_pytest/main.py\", line 839, in _collect_one_node\nINTERNALERROR>     rep = collect_one_node(node)\nINTERNALERROR>           ^^^^^^^^^^^^^^^^^^^^^^\nINTERNALERROR>   File \"/Users/macbookpro/M4_Projects/AIEngineer/backend_ai_popup/venv/lib/python3.11/site-packages/_pytest/runner.py\", line 567, in collect_one_node\nINTERNALERROR>     rep: CollectReport = ihook.pytest_make_collect_report(collector=collector)\nINTERNALERROR>                          ^^^^^^^^^^^^^^^^^^^^^^^^^^^^^^^^^^^^^^^^^^^^^^^^^^^^^\nINTERNALERROR>   File \"/Users/macbookpro/M4_Projects/AIEngineer/backend_ai_popup/venv/lib/python3.11/site-packages/pluggy/_hooks.py\", line 512, in __call__\nINTERNALERROR>     return self._hookexec(self.name, self._hookimpls.copy(), kwargs, firstresult)\nINTERNALERROR>            ^^^^^^^^^^^^^^^^^^^^^^^^^^^^^^^^^^^^^^^^^^^^^^^^^^^^^^^^^^^^^^^^^^^^^^\nINTERNALERROR>   File \"/Users/macbookpro/M4_Projects/AIEngineer/backend_ai_popup/venv/lib/python3.11/site-packages/pluggy/_manager.py\", line 120, in _hookexec\nINTERNALERROR>     return self._inner_hookexec(hook_name, methods, kwargs, firstresult)\nINTERNALERROR>            ^^^^^^^^^^^^^^^^^^^^^^^^^^^^^^^^^^^^^^^^^^^^^^^^^^^^^^^^^^^^^\nINTERNALERROR>   File \"/Users/macbookpro/M4_Projects/AIEngineer/backend_ai_popup/venv/lib/python3.11/site-packages/pluggy/_callers.py\", line 167, in _multicall\nINTERNALERROR>     raise exception\nINTERNALERROR>   File \"/Users/macbookpro/M4_Projects/AIEngineer/backend_ai_popup/venv/lib/python3.11/site-packages/pluggy/_callers.py\", line 139, in _multicall\nINTERNALERROR>     teardown.throw(exception)\nINTERNALERROR>   File \"/Users/macbookpro/M4_Projects/AIEngineer/backend_ai_popup/venv/lib/python3.11/site-packages/_pytest/capture.py\", line 880, in pytest_make_collect_report\nINTERNALERROR>     rep = yield\nINTERNALERROR>           ^^^^^\nINTERNALERROR>   File \"/Users/macbookpro/M4_Projects/AIEngineer/backend_ai_popup/venv/lib/python3.11/site-packages/pluggy/_callers.py\", line 121, in _multicall\nINTERNALERROR>     res = hook_impl.function(*args)\nINTERNALERROR>           ^^^^^^^^^^^^^^^^^^^^^^^^^\nINTERNALERROR>   File \"/Users/macbookpro/M4_Projects/AIEngineer/backend_ai_popup/venv/lib/python3.11/site-packages/_pytest/runner.py\", line 391, in pytest_make_collect_report\nINTERNALERROR>     call = CallInfo.from_call(\nINTERNALERROR>            ^^^^^^^^^^^^^^^^^^^\nINTERNALERROR>   File \"/Users/macbookpro/M4_Projects/AIEngineer/backend_ai_popup/venv/lib/python3.11/site-packages/_pytest/runner.py\", line 344, in from_call\nINTERNALERROR>     result: TResult | None = func()\nINTERNALERROR>                              ^^^^^^\nINTERNALERROR>   File \"/Users/macbookpro/M4_Projects/AIEngineer/backend_ai_popup/venv/lib/python3.11/site-packages/_pytest/runner.py\", line 389, in collect\nINTERNALERROR>     return list(collector.collect())\nINTERNALERROR>                 ^^^^^^^^^^^^^^^^^^^\nINTERNALERROR>   File \"/Users/macbookpro/M4_Projects/AIEngineer/backend_ai_popup/venv/lib/python3.11/site-packages/_pytest/python.py\", line 553, in collect\nINTERNALERROR>     self._register_setup_module_fixture()\nINTERNALERROR>   File \"/Users/macbookpro/M4_Projects/AIEngineer/backend_ai_popup/venv/lib/python3.11/site-packages/_pytest/python.py\", line 566, in _register_setup_module_fixture\nINTERNALERROR>     self.obj, (\"setUpModule\", \"setup_module\")\nINTERNALERROR>     ^^^^^^^^\nINTERNALERROR>   File \"/Users/macbookpro/M4_Projects/AIEngineer/backend_ai_popup/venv/lib/python3.11/site-packages/_pytest/python.py\", line 279, in obj\nINTERNALERROR>     self._obj = obj = self._getobj()\nINTERNALERROR>                       ^^^^^^^^^^^^^^\nINTERNALERROR>   File \"/Users/macbookpro/M4_Projects/AIEngineer/backend_ai_popup/venv/lib/python3.11/site-packages/_pytest/python.py\", line 550, in _getobj\nINTERNALERROR>     return importtestmodule(self.path, self.config)\nINTERNALERROR>            ^^^^^^^^^^^^^^^^^^^^^^^^^^^^^^^^^^^^^^^^\nINTERNALERROR>   File \"/Users/macbookpro/M4_Projects/AIEngineer/backend_ai_popup/venv/lib/python3.11/site-packages/_pytest/python.py\", line 497, in importtestmodule\nINTERNALERROR>     mod = import_path(\nINTERNALERROR>           ^^^^^^^^^^^^\nINTERNALERROR>   File \"/Users/macbookpro/M4_Projects/AIEngineer/backend_ai_popup/venv/lib/python3.11/site-packages/_pytest/pathlib.py\", line 587, in import_path\nINTERNALERROR>     importlib.import_module(module_name)\nINTERNALERROR>   File \"/Library/Frameworks/Python.framework/Versions/3.11/lib/python3.11/importlib/__init__.py\", line 126, in import_module\nINTERNALERROR>     return _bootstrap._gcd_import(name[level:], package, level)\nINTERNALERROR>            ^^^^^^^^^^^^^^^^^^^^^^^^^^^^^^^^^^^^^^^^^^^^^^^^^^^^\nINTERNALERROR>   File \"<frozen importlib._bootstrap>\", line 1204, in _gcd_import\nINTERNALERROR>   File \"<frozen importlib._bootstrap>\", line 1176, in _find_and_load\nINTERNALERROR>   File \"<frozen importlib._bootstrap>\", line 1147, in _find_and_load_unlocked\nINTERNALERROR>   File \"<frozen importlib._bootstrap>\", line 690, in _load_unlocked\nINTERNALERROR>   File \"/Users/macbookpro/M4_Projects/AIEngineer/backend_ai_popup/venv/lib/python3.11/site-packages/_pytest/assertion/rewrite.py\", line 186, in exec_module\nINTERNALERROR>     exec(co, module.__dict__)\nINTERNALERROR>   File \"/Users/macbookpro/M4_Projects/AIEngineer/backend_ai_popup/tests/unit/test_resume_extractor.py\", line 34, in <module>\nINTERNALERROR>     sys.exit(1)\nINTERNALERROR> SystemExit: 1\n\n========================= 3 warnings, 1 error in 0.17s =========================\n",
      "stderr": "mainloop: caught unexpected SystemExit!\n",
      "success": false,
      "command": "pytest -m not slow -v --tb=short tests/"
    }
  ],
  "system_info": {
    "python_version": "3.11.4 (v3.11.4:d2340ef257, Jun  6 2023, 19:15:51) [Clang 13.0.0 (clang-1300.0.29.30)]",
    "pytest_version": "pytest-based",
    "test_runner_version": "3.0.0-pytest",
    "test_structure": "pytest_organized"
  },
  "available_reports": {
    "html_report": "/Users/macbookpro/M4_Projects/AIEngineer/backend_ai_popup/tests/reports/pytest_report.html",
    "coverage_html": "/Users/macbookpro/M4_Projects/AIEngineer/backend_ai_popup/tests/reports/coverage_html/index.html",
    "coverage_json": "/Users/macbookpro/M4_Projects/AIEngineer/backend_ai_popup/tests/reports/coverage.json",
    "junit_xml": "/Users/macbookpro/M4_Projects/AIEngineer/backend_ai_popup/tests/reports/junit.xml"
  }
}