<?xml version="1.0" encoding="utf-8"?><testsuites name="pytest tests"><testsuite name="pytest" errors="2" failures="0" skipped="0" tests="2" time="0.454" timestamp="2025-06-22T13:17:12.800090-05:00" hostname="MacBook-Pro.local"><testcase classname="" name="tests.legacy_tests.test_enhanced_form_filler" time="0.000"><error message="collection failure">ImportError while importing test module '/Users/macbookpro/M4_Projects/AIEngineer/backend_ai_popup/tests/legacy_tests/test_enhanced_form_filler.py'.
Hint: make sure your test modules/packages have valid Python names.
Traceback:
/Library/Frameworks/Python.framework/Versions/3.11/lib/python3.11/importlib/__init__.py:126: in import_module
    return _bootstrap._gcd_import(name[level:], package, level)
           ^^^^^^^^^^^^^^^^^^^^^^^^^^^^^^^^^^^^^^^^^^^^^^^^^^^^
tests/legacy_tests/test_enhanced_form_filler.py:10: in &lt;module&gt;
    from app.services.cache_service import CacheService
E   ModuleNotFoundError: No module named 'app.services.cache_service'</error></testcase><testcase classname="pytest" name="internal" time="0.000"><error message="internal error">Traceback (most recent call last):
  File "/Users/macbookpro/M4_Projects/AIEngineer/backend_ai_popup/tests/legacy_tests/test_resume_extractor.py", line 24, in &lt;module&gt;
    from app.services.resume_extractor_optimized import (
ImportError: cannot import name 'extract_text_from_resume' from 'app.services.resume_extractor_optimized' (/Users/macbookpro/M4_Projects/AIEngineer/backend_ai_popup/app/services/resume_extractor_optimized.py)

During handling of the above exception, another exception occurred:

Traceback (most recent call last):
  File "/Users/macbookpro/M4_Projects/AIEngineer/backend_ai_popup/venv/lib/python3.11/site-packages/_pytest/main.py", line 289, in wrap_session
    session.exitstatus = doit(config, session) or 0
                         ^^^^^^^^^^^^^^^^^^^^^
  File "/Users/macbookpro/M4_Projects/AIEngineer/backend_ai_popup/venv/lib/python3.11/site-packages/_pytest/main.py", line 342, in _main
    config.hook.pytest_collection(session=session)
  File "/Users/macbookpro/M4_Projects/AIEngineer/backend_ai_popup/venv/lib/python3.11/site-packages/pluggy/_hooks.py", line 512, in __call__
    return self._hookexec(self.name, self._hookimpls.copy(), kwargs, firstresult)
           ^^^^^^^^^^^^^^^^^^^^^^^^^^^^^^^^^^^^^^^^^^^^^^^^^^^^^^^^^^^^^^^^^^^^^^
  File "/Users/macbookpro/M4_Projects/AIEngineer/backend_ai_popup/venv/lib/python3.11/site-packages/pluggy/_manager.py", line 120, in _hookexec
    return self._inner_hookexec(hook_name, methods, kwargs, firstresult)
           ^^^^^^^^^^^^^^^^^^^^^^^^^^^^^^^^^^^^^^^^^^^^^^^^^^^^^^^^^^^^^
  File "/Users/macbookpro/M4_Projects/AIEngineer/backend_ai_popup/venv/lib/python3.11/site-packages/pluggy/_callers.py", line 167, in _multicall
    raise exception
  File "/Users/macbookpro/M4_Projects/AIEngineer/backend_ai_popup/venv/lib/python3.11/site-packages/pluggy/_callers.py", line 139, in _multicall
    teardown.throw(exception)
  File "/Users/macbookpro/M4_Projects/AIEngineer/backend_ai_popup/venv/lib/python3.11/site-packages/_pytest/logging.py", line 788, in pytest_collection
    return (yield)
            ^^^^^
  File "/Users/macbookpro/M4_Projects/AIEngineer/backend_ai_popup/venv/lib/python3.11/site-packages/pluggy/_callers.py", line 139, in _multicall
    teardown.throw(exception)
  File "/Users/macbookpro/M4_Projects/AIEngineer/backend_ai_popup/venv/lib/python3.11/site-packages/_pytest/warnings.py", line 99, in pytest_collection
    return (yield)
            ^^^^^
  File "/Users/macbookpro/M4_Projects/AIEngineer/backend_ai_popup/venv/lib/python3.11/site-packages/pluggy/_callers.py", line 139, in _multicall
    teardown.throw(exception)
  File "/Users/macbookpro/M4_Projects/AIEngineer/backend_ai_popup/venv/lib/python3.11/site-packages/_pytest/config/__init__.py", line 1450, in pytest_collection
    return (yield)
            ^^^^^
  File "/Users/macbookpro/M4_Projects/AIEngineer/backend_ai_popup/venv/lib/python3.11/site-packages/pluggy/_callers.py", line 121, in _multicall
    res = hook_impl.function(*args)
          ^^^^^^^^^^^^^^^^^^^^^^^^^
  File "/Users/macbookpro/M4_Projects/AIEngineer/backend_ai_popup/venv/lib/python3.11/site-packages/_pytest/main.py", line 353, in pytest_collection
    session.perform_collect()
  File "/Users/macbookpro/M4_Projects/AIEngineer/backend_ai_popup/venv/lib/python3.11/site-packages/_pytest/main.py", line 813, in perform_collect
    self.items.extend(self.genitems(node))
  File "/Users/macbookpro/M4_Projects/AIEngineer/backend_ai_popup/venv/lib/python3.11/site-packages/_pytest/main.py", line 979, in genitems
    yield from self.genitems(subnode)
  File "/Users/macbookpro/M4_Projects/AIEngineer/backend_ai_popup/venv/lib/python3.11/site-packages/_pytest/main.py", line 979, in genitems
    yield from self.genitems(subnode)
  File "/Users/macbookpro/M4_Projects/AIEngineer/backend_ai_popup/venv/lib/python3.11/site-packages/_pytest/main.py", line 979, in genitems
    yield from self.genitems(subnode)
  File "/Users/macbookpro/M4_Projects/AIEngineer/backend_ai_popup/venv/lib/python3.11/site-packages/_pytest/main.py", line 974, in genitems
    rep, duplicate = self._collect_one_node(node, handle_dupes)
                     ^^^^^^^^^^^^^^^^^^^^^^^^^^^^^^^^^^^^^^^^^^
  File "/Users/macbookpro/M4_Projects/AIEngineer/backend_ai_popup/venv/lib/python3.11/site-packages/_pytest/main.py", line 839, in _collect_one_node
    rep = collect_one_node(node)
          ^^^^^^^^^^^^^^^^^^^^^^
  File "/Users/macbookpro/M4_Projects/AIEngineer/backend_ai_popup/venv/lib/python3.11/site-packages/_pytest/runner.py", line 567, in collect_one_node
    rep: CollectReport = ihook.pytest_make_collect_report(collector=collector)
                         ^^^^^^^^^^^^^^^^^^^^^^^^^^^^^^^^^^^^^^^^^^^^^^^^^^^^^
  File "/Users/macbookpro/M4_Projects/AIEngineer/backend_ai_popup/venv/lib/python3.11/site-packages/pluggy/_hooks.py", line 512, in __call__
    return self._hookexec(self.name, self._hookimpls.copy(), kwargs, firstresult)
           ^^^^^^^^^^^^^^^^^^^^^^^^^^^^^^^^^^^^^^^^^^^^^^^^^^^^^^^^^^^^^^^^^^^^^^
  File "/Users/macbookpro/M4_Projects/AIEngineer/backend_ai_popup/venv/lib/python3.11/site-packages/pluggy/_manager.py", line 120, in _hookexec
    return self._inner_hookexec(hook_name, methods, kwargs, firstresult)
           ^^^^^^^^^^^^^^^^^^^^^^^^^^^^^^^^^^^^^^^^^^^^^^^^^^^^^^^^^^^^^
  File "/Users/macbookpro/M4_Projects/AIEngineer/backend_ai_popup/venv/lib/python3.11/site-packages/pluggy/_callers.py", line 167, in _multicall
    raise exception
  File "/Users/macbookpro/M4_Projects/AIEngineer/backend_ai_popup/venv/lib/python3.11/site-packages/pluggy/_callers.py", line 139, in _multicall
    teardown.throw(exception)
  File "/Users/macbookpro/M4_Projects/AIEngineer/backend_ai_popup/venv/lib/python3.11/site-packages/_pytest/capture.py", line 880, in pytest_make_collect_report
    rep = yield
          ^^^^^
  File "/Users/macbookpro/M4_Projects/AIEngineer/backend_ai_popup/venv/lib/python3.11/site-packages/pluggy/_callers.py", line 121, in _multicall
    res = hook_impl.function(*args)
          ^^^^^^^^^^^^^^^^^^^^^^^^^
  File "/Users/macbookpro/M4_Projects/AIEngineer/backend_ai_popup/venv/lib/python3.11/site-packages/_pytest/runner.py", line 391, in pytest_make_collect_report
    call = CallInfo.from_call(
           ^^^^^^^^^^^^^^^^^^^
  File "/Users/macbookpro/M4_Projects/AIEngineer/backend_ai_popup/venv/lib/python3.11/site-packages/_pytest/runner.py", line 344, in from_call
    result: TResult | None = func()
                             ^^^^^^
  File "/Users/macbookpro/M4_Projects/AIEngineer/backend_ai_popup/venv/lib/python3.11/site-packages/_pytest/runner.py", line 389, in collect
    return list(collector.collect())
                ^^^^^^^^^^^^^^^^^^^
  File "/Users/macbookpro/M4_Projects/AIEngineer/backend_ai_popup/venv/lib/python3.11/site-packages/_pytest/python.py", line 553, in collect
    self._register_setup_module_fixture()
  File "/Users/macbookpro/M4_Projects/AIEngineer/backend_ai_popup/venv/lib/python3.11/site-packages/_pytest/python.py", line 566, in _register_setup_module_fixture
    self.obj, ("setUpModule", "setup_module")
    ^^^^^^^^
  File "/Users/macbookpro/M4_Projects/AIEngineer/backend_ai_popup/venv/lib/python3.11/site-packages/_pytest/python.py", line 279, in obj
    self._obj = obj = self._getobj()
                      ^^^^^^^^^^^^^^
  File "/Users/macbookpro/M4_Projects/AIEngineer/backend_ai_popup/venv/lib/python3.11/site-packages/_pytest/python.py", line 550, in _getobj
    return importtestmodule(self.path, self.config)
           ^^^^^^^^^^^^^^^^^^^^^^^^^^^^^^^^^^^^^^^^
  File "/Users/macbookpro/M4_Projects/AIEngineer/backend_ai_popup/venv/lib/python3.11/site-packages/_pytest/python.py", line 497, in importtestmodule
    mod = import_path(
          ^^^^^^^^^^^^
  File "/Users/macbookpro/M4_Projects/AIEngineer/backend_ai_popup/venv/lib/python3.11/site-packages/_pytest/pathlib.py", line 587, in import_path
    importlib.import_module(module_name)
  File "/Library/Frameworks/Python.framework/Versions/3.11/lib/python3.11/importlib/__init__.py", line 126, in import_module
    return _bootstrap._gcd_import(name[level:], package, level)
           ^^^^^^^^^^^^^^^^^^^^^^^^^^^^^^^^^^^^^^^^^^^^^^^^^^^^
  File "&lt;frozen importlib._bootstrap&gt;", line 1204, in _gcd_import
  File "&lt;frozen importlib._bootstrap&gt;", line 1176, in _find_and_load
  File "&lt;frozen importlib._bootstrap&gt;", line 1147, in _find_and_load_unlocked
  File "&lt;frozen importlib._bootstrap&gt;", line 690, in _load_unlocked
  File "/Users/macbookpro/M4_Projects/AIEngineer/backend_ai_popup/venv/lib/python3.11/site-packages/_pytest/assertion/rewrite.py", line 186, in exec_module
    exec(co, module.__dict__)
  File "/Users/macbookpro/M4_Projects/AIEngineer/backend_ai_popup/tests/legacy_tests/test_resume_extractor.py", line 34, in &lt;module&gt;
    sys.exit(1)
SystemExit: 1</error></testcase></testsuite></testsuites>